<?xml version="1.0" encoding="utf-8"?>
<!-- =================================================================================== -->
<!-- |    This document was autogenerated by xacro from teleop2_robot.urdf.xacro       | -->
<!-- |    EDITING THIS FILE BY HAND IS NOT RECOMMENDED                                 | -->
<!-- =================================================================================== -->
<robot name="teleop2">
  <!-- 
  ROS urdf definition of the TELEOP2 robot by Istituto Italiano di Tecnologia
  
  DO NOT INCLUDE THIS FILE DIRECTLY! USE teleop_robot.urdf.xacro INSTEAD!

  Author: Enrico Mingo

  Inertial matrix has to be in CoM frame (URDF specs)
-->
  <!-- 
  ROS urdf definition of the TELEOP2 robot by Istituto Italiano di Tecnologia
  
  DO NOT INCLUDE THIS FILE DIRECTLY! USE teleop_robot.urdf.xacro INSTEAD!

  Author: Enrico Mingo Hoffman

  Inertial matrix has to be in CoM frame (URDF specs)

-->
  <link name="base_link"/>
  <joint name="base_joint" type="fixed">
    <parent link="base_link"/>
    <child link="teleop2_link0"/>
    <origin rpy="0 0 0" xyz="0 0 0"/>
  </joint>
  <material name="grey">
    <color rgba="0.5 0.5 0.5 1"/>
  </material>
  <material name="red">
    <color rgba="1.0 0.0 0.0 1"/>
  </material>
  <!-- DYNAMICS PARAMETERS NEEDS TO BE CHEKED! -->
  <link name="teleop2_link0">
    <inertial>
      <origin rpy="0 0 0" xyz="0.0 0.0 5e-05"/>
      <mass value="1.5"/>
      <inertia ixx="0.001" ixy="0.0" ixz="0.0" iyy="0.001" iyz="0.0" izz="0.001"/>
    </inertial>
    <visual>
      <origin rpy="0 0 0" xyz="0 0 0"/>
      <geometry name="teleop2_link0_visual">
        <mesh filename="package://vir_singlejoint/robots/6dof/meshes/_teleop2_link0.stl" scale="0.001 0.001 0.001"/>
      </geometry>
      <material name="red"/>
    </visual>
    <collision>
      <origin rpy="0 0 0" xyz="0 0 0"/>
      <geometry name="teleop2_link0_collision">
        <mesh filename="package://vir_singlejoint/robots/6dof/meshes/simple/_teleop2_link0.stl" scale="0.001 0.001 0.001"/>
      </geometry>
    </collision>
  </link>
  <link name="teleop2_link1">
    <inertial>
      <origin rpy="0 0 0" xyz="0.0 -0.02 0.175"/>
      <mass value="0.3"/>
      <inertia ixx="0.001" ixy="0.0" ixz="0.0" iyy="0.001" iyz="0.0" izz="0.0008"/>
    </inertial>
    <visual>
      <origin rpy="0 0 0" xyz="0 0 0"/>
      <geometry name="teleop2_link1_visual">
        <mesh filename="package://vir_singlejoint/robots/6dof/meshes/_teleop2_link1.stl" scale="0.001 0.001 0.001"/>
      </geometry>
      <material name="red"/>
    </visual>
    <collision>
      <origin rpy="0 0 0" xyz="0 0 0"/>
      <geometry name="teleop2_link1_collision">
        <mesh filename="package://vir_singlejoint/robots/6dof/meshes/simple/_teleop2_link1.stl" scale="0.001 0.001 0.001"/>
      </geometry>
    </collision>
  </link>
  <link name="teleop2_link2">
    <inertial>
      <origin rpy="0 0 0" xyz="0.0 0.01 0.18"/>
      <mass value="3.3"/>
      <inertia ixx="0.04" ixy="0.0" ixz="0.0" iyy="0.04" iyz="0.0" izz="0.01"/>
    </inertial>
    <visual>
      <origin rpy="0 0 0" xyz="0 0 0"/>
      <geometry name="teleop2_link2_visual">
        <mesh filename="package://vir_singlejoint/robots/6dof/meshes/_teleop2_link2.stl" scale="0.001 0.001 0.001"/>
      </geometry>
      <material name="red"/>
    </visual>
    <collision>
      <origin rpy="0 0 0" xyz="0 0 0"/>
      <geometry name="teleop2_link2_collision">
        <mesh filename="package://vir_singlejoint/robots/6dof/meshes/simple/_teleop2_link2.stl" scale="0.001 0.001 0.001"/>
      </geometry>
    </collision>
  </link>
  <link name="teleop2_link3">
    <inertial>
      <origin rpy="0 0 0" xyz="0.0 -0.02 0.05"/>
      <mass value="0.3"/>
      <inertia ixx="0.001" ixy="0.0" ixz="0.0" iyy="0.001" iyz="0.0" izz="0.0008"/>
    </inertial>
    <visual>
      <origin rpy="0 0 0" xyz="0 0 0"/>
      <geometry name="teleop2_link3_visual">
        <mesh filename="package://vir_singlejoint/robots/6dof/meshes/_teleop2_link3.stl" scale="0.001 0.001 0.001"/>
      </geometry>
      <material name="red"/>
    </visual>
    <collision>
      <origin rpy="0 0 0" xyz="0 0 0"/>
      <geometry name="teleop2_link3_collision">
        <mesh filename="package://vir_singlejoint/robots/6dof/meshes/simple/_teleop2_link3.stl" scale="0.001 0.001 0.001"/>
      </geometry>
    </collision>
  </link>
  <link name="teleop2_link4">
    <inertial>
      <origin rpy="0 0 0" xyz="0.0 0.0 0.2"/>
      <mass value="2.5"/>
      <inertia ixx="0.015" ixy="0.0" ixz="0.0" iyy="0.015" iyz="0.0" izz="0.008"/>
    </inertial>
    <visual>
      <origin rpy="0 0 0" xyz="0 0 0"/>
      <geometry name="teleop2_link4_visual">
        <mesh filename="package://vir_singlejoint/robots/6dof/meshes/_teleop2_link4.stl" scale="0.001 0.001 0.001"/>
      </geometry>
      <material name="red"/>
    </visual>
    <collision>
      <origin rpy="0 0 0" xyz="0 0 0"/>
      <geometry name="teleop2_link4_collision">
        <mesh filename="package://vir_singlejoint/robots/6dof/meshes/simple/_teleop2_link4.stl" scale="0.001 0.001 0.001"/>
      </geometry>
    </collision>
  </link>
  <link name="teleop2_link5">
    <inertial>
      <origin rpy="0 0 0" xyz="0.0 0.0 0.0"/>
      <mass value="1.2"/>
      <inertia ixx="0.008" ixy="0.0" ixz="0.0" iyy="0.008" iyz="0.0" izz="0.005"/>
    </inertial>
    <visual>
      <origin rpy="0 0 0" xyz="0 0 0"/>
      <geometry name="teleop2_link5_visual">
        <mesh filename="package://vir_singlejoint/robots/6dof/meshes/_teleop2_link5.stl" scale="0.001 0.001 0.001"/>
      </geometry>
      <material name="red"/>
    </visual>
    <collision>
      <origin rpy="0 0 0" xyz="0 0 0"/>
      <geometry name="teleop2_link5_collision">
        <mesh filename="package://vir_singlejoint/robots/6dof/meshes/simple/_teleop2_link5.stl" scale="0.001 0.001 0.001"/>
      </geometry>
    </collision>
  </link>
  <link name="teleop2_link6">
    <inertial>
      <origin rpy="0 0 0" xyz="0.0 0.0 0.12"/>
      <mass value="2.0"/>
      <inertia ixx="0.01" ixy="0.0" ixz="0.0" iyy="0.01" iyz="0.0" izz="0.01"/>
    </inertial>
    <visual>
      <origin rpy="0 0 0" xyz="0 0 0"/>
      <geometry name="teleop2_link6_visual">
        <mesh filename="package://vir_singlejoint/robots/6dof/meshes/_teleop2_link6.stl" scale="0.001 0.001 0.001"/>
      </geometry>
      <material name="red"/>
    </visual>
    <collision>
      <origin rpy="0 0 0" xyz="0 0 0"/>
      <geometry name="teleop2_link6_collision">
        <mesh filename="package://vir_singlejoint/robots/6dof/meshes/simple/_teleop2_link6.stl" scale="0.001 0.001 0.001"/>
      </geometry>
    </collision>
  </link>
  <joint name="joint1" type="revolute">
    <parent link="teleop2_link0"/>
    <child link="teleop2_link1"/>
    <origin rpy="0 0 0" xyz="0.0 0 0"/>
    <axis xyz="0 0 1"/>
    <limit effort="55" lower="-2.79" upper="2.79" velocity="11.7"/>
    <dynamics damping="0.03" friction="0"/>
  </joint>
  <joint name="joint2" type="revolute">
    <parent link="teleop2_link1"/>
    <child link="teleop2_link2"/>
    <origin rpy="0 0 0" xyz="0 0 0.225"/>
    <axis xyz="0 1 0"/>
    <limit effort="147" lower="-2.27" upper="2.27" velocity="5.2"/>
    <dynamics damping="0.03" friction="0"/>
  </joint>
  <joint name="joint3" type="revolute">
    <parent link="teleop2_link2"/>
    <child link="teleop2_link3"/>
    <origin rpy="0 0 0" xyz="0 0 0.365"/>
    <axis xyz="0 1 0"/>
    <limit effort="127" lower="-2.27" upper="2.27" velocity="8.1"/>
    <dynamics damping="0.03" friction="0"/>
  </joint>
  <joint name="joint4" type="revolute">
    <parent link="teleop2_link3"/>
    <child link="teleop2_link4"/>
    <origin rpy="0 0 0" xyz="0 0 0"/>
    <axis xyz="0 0 1"/>
    <limit effort="28" lower="-2.79" upper="2.79" velocity="20.4"/>
    <dynamics damping="0.03" friction="0"/>
  </joint>
  <joint name="joint5" type="revolute">
    <parent link="teleop2_link4"/>
    <child link="teleop2_link5"/>
    <origin rpy="0 0 0" xyz="0 0 0.335"/>
    <axis xyz="0 1 0"/>
    <limit effort="28" lower="-2.36" upper="2.36" velocity="20.4"/>
    <dynamics damping="0.03" friction="0"/>
  </joint>
  <joint name="joint6" type="revolute">
    <parent link="teleop2_link5"/>
    <child link="teleop2_link6"/>
    <origin rpy="0 0 0" xyz="0 0 0"/>
    <axis xyz="0 0 1"/>
    <limit effort="28" lower="-2.62" upper="2.62" velocity="20.4"/>
    <dynamics damping="0.03" friction="0"/>
  </joint>
  <link name="world"/>
  <joint name="world_joint" type="fixed">
    <parent link="world"/>
    <child link="base_link"/>
  </joint>
  <origin rpy="0 0 3.14159265359" xyz="0 0 0.05"/>
  <!--link name="TCP"/>
<joint name="TCP_joint" type="fixed">
	<parent link="teleop_link6"/>
	<child link="TCP"/>
	<origin xyz="0 0 ${170.*mmTom}" rpy="0 0 0" />
</joint-->
  <gazebo reference="joint1">
    <implicitSpringDamper>1</implicitSpringDamper>
    <provideFeedback>true</provideFeedback>
  </gazebo>
  <gazebo reference="joint2">
    <implicitSpringDamper>1</implicitSpringDamper>
    <provideFeedback>true</provideFeedback>
  </gazebo>
  <gazebo reference="joint3">
    <implicitSpringDamper>1</implicitSpringDamper>
    <provideFeedback>true</provideFeedback>
  </gazebo>
  <gazebo reference="joint4">
    <implicitSpringDamper>1</implicitSpringDamper>
    <provideFeedback>true</provideFeedback>
  </gazebo>
  <gazebo reference="joint5">
    <implicitSpringDamper>1</implicitSpringDamper>
    <provideFeedback>true</provideFeedback>
  </gazebo>
  <gazebo reference="joint6">
    <implicitSpringDamper>1</implicitSpringDamper>
    <provideFeedback>true</provideFeedback>
  </gazebo>
  <gazebo reference="teleop2_link0">
    <material>Gazebo/Green</material>
  </gazebo>
  <gazebo reference="teleop2_link1">
    <material>Gazebo/DarkGrey</material>
  </gazebo>
  <gazebo reference="teleop2_link2">
    <material>Gazebo/Green</material>
  </gazebo>
  <gazebo reference="teleop2_link3">
    <material>Gazebo/DarkGrey</material>
  </gazebo>
  <gazebo reference="teleop2_link4">
    <material>Gazebo/DarkGrey</material>
  </gazebo>
  <gazebo reference="teleop2_link5">
    <material>Gazebo/DarkGrey</material>
  </gazebo>
  <gazebo reference="teleop2_link6">
    <material>Gazebo/DarkGrey</material>
  </gazebo>
  <!--xacro:include filename="$(find cogimon_urdf)/urdf/gazebo/force_torque.gazebo.xacro" /-->
  <gazebo>
    <plugin filename="libxbot2_gz_joint_server.so" name="xbot2_gz_joint_server">
      <pid>
        <gain d="5" name="small_mot" p="100"/>
        <pid name="joint1" profile="small_motor"/>
        <pid name="joint2" profile="small_motor"/>
        <pid name="joint3" profile="small_motor"/>
        <pid name="joint4" profile="small_motor"/>
        <pid name="joint5" profile="small_motor"/>
        <pid name="joint6" profile="small_motor"/>
      </pid>
    </plugin>
    <plugin filename="libxbot2_gz_ft_server.so" name="xbot2_ft_driver"/>
    <plugin filename="libxbot2_gz_imu_server.so" name="xbot2_imu_driver"/>
  </gazebo>
</robot>

